Workbook

Sheet Matrix
B1: KEY | C1: 1=Absent | D1: 2=Minimal | E1: 3=Basic | F1: 4=Strong | G1: 5=Best In Class
A3: Feature | B3: Bloomberg | C3: Robinhood | D3: Fidelity | E3: Investopedia Sim | F3: TradingView | G3: Ally Invest | H3: Empower | I3: Charles Schwab | J3: TD Bank | K3: T. Rowe Price | L3: Vanguard | M3: Webull | N3: Average Score | O3: Last Reviewed | P3: Notes
A4: Cost
A5: Monetiation Strategy | B5: Monthly Subsription | C5: Monthly Subsription | D5: Advisory Fee | E5: FREE | F5: Monthly Subsription | G5: Advisory Fee | H5: Not specified | I5: Various | J5: Flat Fee per contract | K5: Advisory Fee | L5: Per Trade | M5: Various | O5: 45996
A6: Lowest tier cost | B6: 2020 | C6: 0 | D6: Free | F6: 12.95 | G6: 0 | H6: 0 | I6: 0 | J6: 9.99 | K6: Various | L6: 0 | M6: Regulatory Fee based on volume | O6: 45996
A7: Middle tier cost | B7: - | C7: - | D7: 0.0035 | F7: 56.49 | G7: 0.003 | I7: Various | K7: Various | M7: - | O7: 46016
A8: highest tier cost | B8: =32000/12 -> 2666.6667 | C8: 5 | D8: 0.015 | F8: 199 | G8: 0.0085 | I8: 30 | J8: 7 | K8: Various | L8: 25 | M8: 3.99 | O8: 46016
A9: User Profile & Target Segment | B9: =SUM(B10:B13) -> 2.5 | C9: =SUM(C10:C13) -> 3.75 | D9: =SUM(D10:D13) -> 3.75 | E9: =SUM(E10:E13) -> 2.5 | F9: =SUM(F10:F13) -> 3.75 | G9: =SUM(G10:G13) -> 3.75 | H9: =SUM(H10:H13) -> 2.5 | I9: =SUM(I10:I13) -> 3.75 | ... M9: =SUM(M10:M13) -> 3.75 | P9: Special Scale, each target user profile gets 1.25 points.
A10: Retail beginner | B10: - | C10: 1.25 | D10: 1.25 | E10: 1.25 | F10: 1.25 | G10: 1.25 | H10: 1.25 | I10: 1.25 | J10: 1.25 | K10: 1.25 | L10: 1.25 | M10: 1.25 | O10: 45996
A11: Retail intermediate | B11: - | C11: 1.25 | D11: 1.25 | E11: 1.25 | F11: 1.25 | G11: 1.25 | H11: 1.25 | I11: 1.25 | J11: 1.25 | K11: 1.25 | L11: 1.25 | M11: 1.25 | O11: 45996
A12: Advanced / active trader | B12: 1.25 | C12: 1.25 | D12: 1.25 | E12: - | F12: 1.25 | G12: 1.25 | I12: 1.25 | J12: 1.25 | M12: 1.25 | O12: 45996
A13: Professional / institutional | B13: 1.25 | C13: - | D13: - | E13: - | F13: - | O13: 45996
A14: Learning, Training & Simulation | B14: =AVERAGE(B17:B21) -> 4 | C14: =AVERAGE(C17:C21) -> 2.8 | D14: =AVERAGE(D17:D21) -> 3.2 | E14: =AVERAGE(E17:E21) -> 3.2 | F14: =AVERAGE(F17:F21) -> 2.4 | G14: =AVERAGE(G17:G21) -> 3.2 | H14: =AVERAGE(H17:H21) -> 2.6 | I14: =AVERAGE(I17:I21) -> 3.8 | ... M14: =AVERAGE(M17:M21) -> 2.4 | N14: =AVERAGE(B14:M14) -> 2.95
A15: Finance 101 - Entry level learning content | B15: 1 | C15: 5 | D15: 5 | E15: 5 | F15: 1 | G15: 4 | H15: 3 | I15: 4 | J15: 1 | K15: 2 | L15: 3 | M15: 5 | N15: =AVERAGE(B15:M15) -> 3.25 | O15: 45996
A16: Advanced Training (Puts, Shorting, other adv methods) | B16: 1 | C16: 3 | D16: 3 | E16: 2 | F16: 1 | G16: 3 | H16: 1 | I16: 4 | J16: 1 | K16: 1 | L16: 2 | M16: 5 | N16: =AVERAGE(B16:M16) -> 2.25 | O16: 45996
A17: Paper trading Simulator? | B17: 4 | C17: 4 | D17: 3 | E17: 3 | F17: 2 | G17: 3 | H17: 3 | I17: 3 | J17: 3 | K17: 2 | L17: 3 | M17: 4 | N17: =AVERAGE(B17:M17) -> 3.0833333 | O17: 45996
A18: Tutorials | B18: 5 | C18: 2 | D18: 3 | E18: 3 | F18: 3 | G18: 3 | H18: 2 | I18: 3 | J18: 4 | K18: 2 | L18: 2 | M18: 2 | N18: =AVERAGE(B18:M18) -> 2.8333333 | O18: 45996
A19: Quizzes | B19: 5 | C19: 3 | D19: 3 | E19: 5 | F19: 1 | G19: 4 | H19: 3 | I19: 4 | J19: 1 | K19: 2 | L19: 2 | M19: 1 | N19: =AVERAGE(B19:M19) -> 2.8333333 | O19: 45996
A20: Software Training - how to use platform features | B20: 4 | C20: 3 | D20: 4 | E20: 3 | F20: 4 | G20: 3 | H20: 3 | I20: 4 | J20: 3 | K20: 3 | L20: 3 | M20: 3 | N20: =AVERAGE(B20:M20) -> 3.3333333 | O20: 45996
A21: Guided trade features | B21: 2 | C21: 2 | D21: 3 | E21: 2 | F21: 2 | G21: 3 | H21: 2 | I21: 5 | J21: 2 | K21: 3 | L21: 4 | M21: 2 | N21: =AVERAGE(B21:M21) -> 2.6666667 | O21: 45996
A22: Asset Classes Supported | B22: =AVERAGE(B23:B31) -> 3.6666667 | C22: =AVERAGE(C23:C31) -> 3.2222222 | D22: =AVERAGE(D23:D31) -> 3.5555556 | E22: =AVERAGE(E23:E31) -> 3.3333333 | F22: =AVERAGE(F23:F31) -> 3.1111111 | G22: =AVERAGE(G23:G31) -> 2.8888889 | H22: =AVERAGE(H23:H31) -> 3.6666667 | I22: =AVERAGE(I23:I31) -> 3.3333333 | ... M22: =AVERAGE(M23:M31) -> 2.7777778 | N22: =AVERAGE(B22:M22) -> 3.4166667 | P22: **The data in the rows below were AI generated and need to be verified
A23: Stocks | B23: 4 | C23: 3 | D23: 4 | E23: 2 | F23: 3 | G23: 2 | H23: 5 | I23: 4 | J23: 2 | K23: 3 | L23: 4 | M23: 3 | N23: =AVERAGE(B23:M23) -> 3.25 | P23: THIS ROW TEMPLATE ONLY
A24: ETFs | B24: 5 | C24: 5 | D24: 5 | E24: 3 | F24: 4 | G24: 3 | H24: 4 | I24: 5 | J24: 5 | K24: 4 | L24: 3 | M24: 3 | N24: =AVERAGE(B24:M24) -> 4.0833333 | P24: THIS ROW TEMPLATE ONLY
A25: Mutual funds | B25: 5 | C25: 2 | D25: 2 | E25: 2 | F25: 3 | G25: 3 | H25: 2 | I25: 5 | J25: 5 | K25: 5 | L25: 4 | M25: 2 | N25: =AVERAGE(B25:M25) -> 3.3333333 | P25: THIS ROW TEMPLATE ONLY
A26: Options | B26: 2 | C26: 4 | D26: 4 | E26: 2 | F26: 4 | G26: 5 | H26: 5 | I26: 2 | J26: 4 | K26: 3 | L26: 2 | M26: 4 | N26: =AVERAGE(B26:M26) -> 3.4166667 | P26: THIS ROW TEMPLATE ONLY
A27: Futures | B27: 3 | C27: 3 | D27: 4 | E27: 3 | F27: 2 | G27: 4 | H27: 2 | I27: 2 | J27: 4 | K27: 4 | L27: 3 | M27: 2 | N27: =AVERAGE(B27:M27) -> 3 | P27: THIS ROW TEMPLATE ONLY
A28: Forex | B28: 3 | C28: 2 | D28: 2 | E28: 5 | F28: 2 | G28: 3 | H28: 5 | I28: 3 | J28: 4 | K28: 5 | L28: 3 | M28: 3 | N28: =AVERAGE(B28:M28) -> 3.3333333 | P28: THIS ROW TEMPLATE ONLY
A29: Crypto | B29: 4 | C29: 5 | D29: 4 | E29: 5 | F29: 5 | G29: 2 | H29: 3 | I29: 2 | J29: 4 | K29: 2 | L29: 3 | M29: 3 | N29: =AVERAGE(B29:M29) -> 3.5 | P29: THIS ROW TEMPLATE ONLY
A30: Fixed income | B30: 2 | C30: 2 | D30: 2 | E30: 3 | F30: 2 | G30: 2 | H30: 2 | I30: 3 | J30: 4 | K30: 5 | L30: 3 | M30: 3 | N30: =AVERAGE(B30:M30) -> 2.75 | P30: THIS ROW TEMPLATE ONLY
A31: Alternatives (private equity, structured products) | B31: 5 | C31: 3 | D31: 5 | E31: 5 | F31: 3 | G31: 2 | H31: 5 | I31: 4 | J31: 5 | K31: 5 | L31: 5 | M31: 2 | N31: =AVERAGE(B31:M31) -> 4.0833333 | P31: THIS ROW TEMPLATE ONLY
A32: Account Types & Brokerage Functionality | B32: =AVERAGE(B33:B38) -> 3 | C32: =AVERAGE(C33:C38) -> 3.3333333 | D32: =AVERAGE(D33:D38) -> 3.3333333 | E32: =AVERAGE(E33:E38) -> 3.6666667 | F32: =AVERAGE(F33:F38) -> 2.8333333 | G32: =AVERAGE(G33:G38) -> 3.1666667 | H32: =AVERAGE(H33:H38) -> 2.5 | I32: =AVERAGE(I33:I38) -> 4.1666667 | ... M32: =AVERAGE(M33:M38) -> 3.6666667 | N32: =AVERAGE(B32:M32) -> 3.375 | P32: **The data in the rows below were AI generated and need to be verified
A33: Standard brokerage | B33: 2 | C33: 2 | D33: 5 | E33: 4 | F33: 2 | G33: 3 | H33: 3 | I33: 5 | J33: 3 | K33: 5 | L33: 3 | M33: 4 | N33: =AVERAGE(B33:M33) -> 3.4166667 | P33: THIS ROW TEMPLATE ONLY
A34: Retirement accounts (IRA, Roth) | B34: 5 | C34: 3 | D34: 2 | E34: 5 | F34: 2 | G34: 2 | H34: 2 | I34: 3 | J34: 3 | K34: 5 | L34: 5 | M34: 5 | N34: =AVERAGE(B34:M34) -> 3.5 | P34: THIS ROW TEMPLATE ONLY
A35: Margin accounts | B35: 3 | C35: 5 | D35: 2 | E35: 3 | F35: 5 | G35: 2 | H35: 4 | I35: 5 | J35: 4 | K35: 5 | L35: 5 | M35: 3 | N35: =AVERAGE(B35:M35) -> 3.8333333 | P35: THIS ROW TEMPLATE ONLY
A36: Custodial accounts | B36: 3 | C36: 4 | D36: 3 | E36: 2 | F36: 2 | G36: 4 | H36: 2 | I36: 5 | J36: 3 | K36: 2 | L36: 2 | M36: 3 | N36: =AVERAGE(B36:M36) -> 2.9166667 | P36: THIS ROW TEMPLATE ONLY
A37: Fractional shares | B37: 2 | C37: 2 | D37: 3 | E37: 5 | F37: 2 | G37: 3 | H37: 2 | I37: 5 | J37: 4 | K37: 4 | L37: 3 | M37: 4 | N37: =AVERAGE(B37:M37) -> 3.25 | P37: THIS ROW TEMPLATE ONLY
A38: Automated investing / robo-advisor | B38: 3 | C38: 4 | D38: 5 | E38: 3 | F38: 4 | G38: 5 | H38: 2 | I38: 2 | J38: 5 | K38: 2 | L38: 2 | M38: 3 | N38: =AVERAGE(B38:M38) -> 3.3333333 | P38: THIS ROW TEMPLATE ONLY
A39: Trading Tools | B39: =AVERAGE(B40:B46) -> 3.1428571 | C39: =AVERAGE(C40:C46) -> 2.8571429 | D39: =AVERAGE(D40:D46) -> 3.1428571 | E39: =AVERAGE(E40:E46) -> 2.8571429 | F39: =AVERAGE(F40:F46) -> 3.4285714 | G39: =AVERAGE(G40:G46) -> 3.5714286 | H39: =AVERAGE(H40:H46) -> 3.1428571 | I39: =AVERAGE(I40:I46) -> 3.5714286 | ... M39: =AVERAGE(M40:M46) -> 3.1428571 | N39: =AVERAGE(B39:M39) -> 3.3571429 | P39: **The data in the rows below were AI generated and need to be verified
A40: Order types | B40: 4 | C40: 3 | D40: 4 | E40: 2 | F40: 3 | G40: 4 | H40: 3 | I40: 5 | J40: 4 | K40: 2 | L40: 4 | M40: 2 | N40: =AVERAGE(B40:M40) -> 3.3333333 | P40: THIS ROW TEMPLATE ONLY
A41: Advanced order routing | B41: 3 | C41: 4 | D41: 2 | E41: 2 | F41: 3 | G41: 4 | H41: 3 | I41: 4 | J41: 3 | K41: 4 | L41: 5 | M41: 4 | N41: =AVERAGE(B41:M41) -> 3.4166667 | P41: THIS ROW TEMPLATE ONLY
...

Sheet Learning Dashboard
A1: Learning, Training & Simulation | B1: =Matrix!B3 -> Bloomberg | C1: =Matrix!C3 -> Robinhood | D1: =Matrix!D3 -> Fidelity | E1: =Matrix!E3 -> Investopedia Sim | F1: =Matrix!F3 -> TradingView | G1: =Matrix!G3 -> Ally Invest | H1: =Matrix!H3 -> Empower | I1: =Matrix!I3 -> Charles Schwab | ... M1: =Matrix!M3 -> Webull
A2: Entry level learning content | B2: =Matrix!B15 -> 1 | C2: =Matrix!C15 -> 5 | D2: =Matrix!D15 -> 5 | E2: =Matrix!E15 -> 5 | F2: =Matrix!F15 -> 1 | G2: =Matrix!G15 -> 4 | H2: =Matrix!H15 -> 3 | I2: =Matrix!I15 -> 4 | ... M2: =Matrix!M15 -> 5 | P2: Takeaways
A3: Advanced Training | B3: =Matrix!B16 -> 1 | C3: =Matrix!C16 -> 3 | D3: =Matrix!D16 -> 3 | E3: =Matrix!E16 -> 2 | F3: =Matrix!F16 -> 1 | G3: =Matrix!G16 -> 3 | H3: =Matrix!H16 -> 1 | I3: =Matrix!I16 -> 4 | ... M3: =Matrix!M16 -> 5 | P3: Even platforms with the highest cumulative score lack in some areas
A4: Paper trading Sim | B4: =Matrix!B17 -> 4 | C4: =Matrix!C17 -> 4 | D4: =Matrix!D17 -> 3 | E4: =Matrix!E17 -> 3 | F4: =Matrix!F17 -> 2 | G4: =Matrix!G17 -> 3 | H4: =Matrix!H17 -> 3 | I4: =Matrix!I17 -> 3 | ... M4: =Matrix!M17 -> 4 | Q4: Guided Trading
A5: Tutorials | B5: =Matrix!B18 -> 5 | C5: =Matrix!C18 -> 2 | D5: =Matrix!D18 -> 3 | E5: =Matrix!E18 -> 3 | F5: =Matrix!F18 -> 3 | G5: =Matrix!G18 -> 3 | H5: =Matrix!H18 -> 2 | I5: =Matrix!I18 -> 3 | ... M5: =Matrix!M18 -> 2
A6: Quizzes | B6: =Matrix!B19 -> 5 | C6: =Matrix!C19 -> 3 | D6: =Matrix!D19 -> 3 | E6: =Matrix!E19 -> 5 | F6: =Matrix!F19 -> 1 | G6: =Matrix!G19 -> 4 | H6: =Matrix!H19 -> 3 | I6: =Matrix!I19 -> 4 | ... M6: =Matrix!M19 -> 1
A7: Software Training | B7: =Matrix!B20 -> 4 | C7: =Matrix!C20 -> 3 | D7: =Matrix!D20 -> 4 | E7: =Matrix!E20 -> 3 | F7: =Matrix!F20 -> 4 | G7: =Matrix!G20 -> 3 | H7: =Matrix!H20 -> 3 | I7: =Matrix!I20 -> 4 | ... M7: =Matrix!M20 -> 3
A8: Guided trade features | B8: =Matrix!B21 -> 2 | C8: =Matrix!C21 -> 2 | D8: =Matrix!D21 -> 3 | E8: =Matrix!E21 -> 2 | F8: =Matrix!F21 -> 2 | G8: =Matrix!G21 -> 3 | H8: =Matrix!H21 -> 2 | I8: =Matrix!I21 -> 5 | ... M8: =Matrix!M21 -> 2
A9: Total | B9: =SUM(B2:B8) -> 22 | C9: =SUM(C2:C8) -> 22 | D9: =SUM(D2:D8) -> 24 | E9: =SUM(E2:E8) -> 23 | F9: =SUM(F2:F8) -> 14 | G9: =SUM(G2:G8) -> 23 | H9: =SUM(H2:H8) -> 17 | I9: =SUM(I2:I8) -> 27 | ... M9: =SUM(M2:M8) -> 22 | O9: 1=Absent | P9: 2=Minimal | Q9: 3=Basic | R9: 4=Strong | S9: 5=Best In Class
